Workbook

Sheet Summary
A1: HRMS — Test Case Report
A3: Application | B3: Progbiz HRMS — https://hrms-test.progbiz.in (company pbhrms)
A4: Scope | B4: All HRMS modules (sidebar), public career page, cross-module journeys, non-functional
A5: Automation suite | B5: Playwright linear run — hrms/tests/00_linear/hrms_linear_run.spec.js (128 pages, one tab)
A6: Last automated run | B6: 19 Oct 2026 — full headed run, 128/128 page checks passed; all actions green after fixes
A7: Report generated | B7: 20 Oct 2026
A10: Module (sheet) | B10: Total | C10: High | D10: Positive | E10: Negative | F10: Automated (Linear Run) | G10: Automated (Page Check) | H10: Not Automated | I10: Blocked | J10: Out of Scope | K10: Passed | L10: % Automated | M10: % Executed
A11: Login & Navigation | B11: =COUNTA('Login & Navigation'!$A$2:$A$92) -> 91 | C11: =COUNTIF('Login & Navigation'!$L$2:$L$92,"High") -> 44 | D11: =COUNTIF('Login & Navigation'!$J$2:$J$92,"Positive") -> 27 | E11: =COUNTIF('Login & Navigation'!$J$2:$J$92,"Negative") -> 11 | F11: =COUNTIF('Login & Navigation'!$M$2:$M$92,"Automated (Linear Run)") -> 4 | G11: =COUNTIF('Login & Navigation'!$M$2:$M$92,"Automated (Page Check)") -> 1 | H11: =COUNTIF('Login & Navigation'!$M$2:$M$92,"Not Automated") -> 84 | I11: =COUNTIF('Login & Navigation'!$M$2:$M$92,"Blocked") -> 2 | J11: =COUNTIF('Login & Navigation'!$M$2:$M$92,"Out of Scope") -> 0 | K11: =COUNTIF('Login & Navigation'!$O$2:$O$92,"Passed*") -> 5 | L11: =IF(B11=0,0,(F11+G11)/B11) -> 0.054945055 | M11: =IF(B11=0,0,K11/B11) -> 0.054945055
A12: Core HR | B12: =COUNTA('Core HR'!$A$2:$A$295) -> 294 | C12: =COUNTIF('Core HR'!$L$2:$L$295,"High") -> 98 | D12: =COUNTIF('Core HR'!$J$2:$J$295,"Positive") -> 105 | E12: =COUNTIF('Core HR'!$J$2:$J$295,"Negative") -> 46 | F12: =COUNTIF('Core HR'!$M$2:$M$295,"Automated (Linear Run)") -> 31 | G12: =COUNTIF('Core HR'!$M$2:$M$295,"Automated (Page Check)") -> 11 | H12: =COUNTIF('Core HR'!$M$2:$M$295,"Not Automated") -> 252 | I12: =COUNTIF('Core HR'!$M$2:$M$295,"Blocked") -> 0 | J12: =COUNTIF('Core HR'!$M$2:$M$295,"Out of Scope") -> 0 | K12: =COUNTIF('Core HR'!$O$2:$O$295,"Passed*") -> 42 | L12: =IF(B12=0,0,(F12+G12)/B12) -> 0.14285714 | M12: =IF(B12=0,0,K12/B12) -> 0.14285714
A13: Recruitment | B13: =COUNTA('Recruitment'!$A$2:$A$341) -> 340 | C13: =COUNTIF('Recruitment'!$L$2:$L$341,"High") -> 101 | D13: =COUNTIF('Recruitment'!$J$2:$J$341,"Positive") -> 120 | E13: =COUNTIF('Recruitment'!$J$2:$J$341,"Negative") -> 38 | F13: =COUNTIF('Recruitment'!$M$2:$M$341,"Automated (Linear Run)") -> 39 | G13: =COUNTIF('Recruitment'!$M$2:$M$341,"Automated (Page Check)") -> 12 | H13: =COUNTIF('Recruitment'!$M$2:$M$341,"Not Automated") -> 283 | I13: =COUNTIF('Recruitment'!$M$2:$M$341,"Blocked") -> 6 | J13: =COUNTIF('Recruitment'!$M$2:$M$341,"Out of Scope") -> 0 | K13: =COUNTIF('Recruitment'!$O$2:$O$341,"Passed*") -> 51 | L13: =IF(B13=0,0,(F13+G13)/B13) -> 0.15 | M13: =IF(B13=0,0,K13/B13) -> 0.15
A14: Referral | B14: =COUNTA('Referral'!$A$2:$A$84) -> 83 | C14: =COUNTIF('Referral'!$L$2:$L$84,"High") -> 25 | D14: =COUNTIF('Referral'!$J$2:$J$84,"Positive") -> 24 | E14: =COUNTIF('Referral'!$J$2:$J$84,"Negative") -> 13 | F14: =COUNTIF('Referral'!$M$2:$M$84,"Automated (Linear Run)") -> 13 | G14: =COUNTIF('Referral'!$M$2:$M$84,"Automated (Page Check)") -> 3 | H14: =COUNTIF('Referral'!$M$2:$M$84,"Not Automated") -> 55 | I14: =COUNTIF('Referral'!$M$2:$M$84,"Blocked") -> 0 | J14: =COUNTIF('Referral'!$M$2:$M$84,"Out of Scope") -> 12 | K14: =COUNTIF('Referral'!$O$2:$O$84,"Passed*") -> 16 | L14: =IF(B14=0,0,(F14+G14)/B14) -> 0.19277108 | M14: =IF(B14=0,0,K14/B14) -> 0.19277108
A15: Onboarding & Probation | B15: =COUNTA('Onboarding & Probation'!$A$2:$A$239) -> 238 | C15: =COUNTIF('Onboarding & Probation'!$L$2:$L$239,"High") -> 84 | D15: =COUNTIF('Onboarding & Probation'!$J$2:$J$239,"Positive") -> 79 | E15: =COUNTIF('Onboarding & Probation'!$J$2:$J$239,"Negative") -> 37 | F15: =COUNTIF('Onboarding & Probation'!$M$2:$M$239,"Automated (Linear Run)") -> 3 | G15: =COUNTIF('Onboarding & Probation'!$M$2:$M$239,"Automated (Page Check)") -> 15 | H15: =COUNTIF('Onboarding & Probation'!$M$2:$M$239,"Not Automated") -> 202 | I15: =COUNTIF('Onboarding & Probation'!$M$2:$M$239,"Blocked") -> 18 | J15: =COUNTIF('Onboarding & Probation'!$M$2:$M$239,"Out of Scope") -> 0 | K15: =COUNTIF('Onboarding & Probation'!$O$2:$O$239,"Passed*") -> 18 | L15: =IF(B15=0,0,(F15+G15)/B15) -> 0.075630252 | M15: =IF(B15=0,0,K15/B15) -> 0.075630252
A16: Attendance | B16: =COUNTA('Attendance'!$A$2:$A$170) -> 169 | C16: =COUNTIF('Attendance'!$L$2:$L$170,"High") -> 51 | D16: =COUNTIF('Attendance'!$J$2:$J$170,"Positive") -> 55 | E16: =COUNTIF('Attendance'!$J$2:$J$170,"Negative") -> 26 | F16: =COUNTIF('Attendance'!$M$2:$M$170,"Automated (Linear Run)") -> 0 | G16: =COUNTIF('Attendance'!$M$2:$M$170,"Automated (Page Check)") -> 8 | H16: =COUNTIF('Attendance'!$M$2:$M$170,"Not Automated") -> 138 | I16: =COUNTIF('Attendance'!$M$2:$M$170,"Blocked") -> 23 | J16: =COUNTIF('Attendance'!$M$2:$M$170,"Out of Scope") -> 0 | K16: =COUNTIF('Attendance'!$O$2:$O$170,"Passed*") -> 8 | L16: =IF(B16=0,0,(F16+G16)/B16) -> 0.047337278 | M16: =IF(B16=0,0,K16/B16) -> 0.047337278
A17: Leave | B17: =COUNTA('Leave'!$A$2:$A$296) -> 295 | C17: =COUNTIF('Leave'!$L$2:$L$296,"High") -> 84 | D17: =COUNTIF('Leave'!$J$2:$J$296,"Positive") -> 86 | E17: =COUNTIF('Leave'!$J$2:$J$296,"Negative") -> 55 | F17: =COUNTIF('Leave'!$M$2:$M$296,"Automated (Linear Run)") -> 11 | G17: =COUNTIF('Leave'!$M$2:$M$296,"Automated (Page Check)") -> 13 | H17: =COUNTIF('Leave'!$M$2:$M$296,"Not Automated") -> 269 | I17: =COUNTIF('Leave'!$M$2:$M$296,"Blocked") -> 0 | J17: =COUNTIF('Leave'!$M$2:$M$296,"Out of Scope") -> 2 | K17: =COUNTIF('Leave'!$O$2:$O$296,"Passed*") -> 24 | L17: =IF(B17=0,0,(F17+G17)/B17) -> 0.081355932 | M17: =IF(B17=0,0,K17/B17) -> 0.081355932
A18: Payroll | B18: =COUNTA('Payroll'!$A$2:$A$286) -> 285 | C18: =COUNTIF('Payroll'!$L$2:$L$286,"High") -> 120 | D18: =COUNTIF('Payroll'!$J$2:$J$286,"Positive") -> 88 | E18: =COUNTIF('Payroll'!$J$2:$J$286,"Negative") -> 41 | F18: =COUNTIF('Payroll'!$M$2:$M$286,"Automated (Linear Run)") -> 0 | G18: =COUNTIF('Payroll'!$M$2:$M$286,"Automated (Page Check)") -> 30 | H18: =COUNTIF('Payroll'!$M$2:$M$286,"Not Automated") -> 236 | I18: =COUNTIF('Payroll'!$M$2:$M$286,"Blocked") -> 0 | J18: =COUNTIF('Payroll'!$M$2:$M$286,"Out of Scope") -> 19 | K18: =COUNTIF('Payroll'!$O$2:$O$286,"Passed*") -> 30 | L18: =IF(B18=0,0,(F18+G18)/B18) -> 0.10526316 | M18: =IF(B18=0,0,K18/B18) -> 0.10526316
A19: Resignation & Exit | B19: =COUNTA('Resignation & Exit'!$A$2:$A$182) -> 181 | C19: =COUNTIF('Resignation & Exit'!$L$2:$L$182,"High") -> 67 | D19: =COUNTIF('Resignation & Exit'!$J$2:$J$182,"Positive") -> 51 | E19: =COUNTIF('Resignation & Exit'!$J$2:$J$182,"Negative") -> 28 | F19: =COUNTIF('Resignation & Exit'!$M$2:$M$182,"Automated (Linear Run)") -> 0 | G19: =COUNTIF('Resignation & Exit'!$M$2:$M$182,"Automated (Page Check)") -> 15 | H19: =COUNTIF('Resignation & Exit'!$M$2:$M$182,"Not Automated") -> 146 | I19: =COUNTIF('Resignation & Exit'!$M$2:$M$182,"Blocked") -> 1 | J19: =COUNTIF('Resignation & Exit'!$M$2:$M$182,"Out of Scope") -> 19 | K19: =COUNTIF('Resignation & Exit'!$O$2:$O$182,"Passed*") -> 15 | L19: =IF(B19=0,0,(F19+G19)/B19) -> 0.082872928 | M19: =IF(B19=0,0,K19/B19) -> 0.082872928
A20: My Workspace (ESS) | B20: =COUNTA('My Workspace (ESS)'!$A$2:$A$210) -> 209 | C20: =COUNTIF('My Workspace (ESS)'!$L$2:$L$210,"High") -> 96 | D20: =COUNTIF('My Workspace (ESS)'!$J$2:$J$210,"Positive") -> 67 | E20: =COUNTIF('My Workspace (ESS)'!$J$2:$J$210,"Negative") -> 27 | F20: =COUNTIF('My Workspace (ESS)'!$M$2:$M$210,"Automated (Linear Run)") -> 6 | G20: =COUNTIF('My Workspace (ESS)'!$M$2:$M$210,"Automated (Page Check)") -> 22 | H20: =COUNTIF('My Workspace (ESS)'!$M$2:$M$210,"Not Automated") -> 179 | I20: =COUNTIF('My Workspace (ESS)'!$M$2:$M$210,"Blocked") -> 2 | J20: =COUNTIF('My Workspace (ESS)'!$M$2:$M$210,"Out of Scope") -> 0 | K20: =COUNTIF('My Workspace (ESS)'!$O$2:$O$210,"Passed*") -> 28 | L20: =IF(B20=0,0,(F20+G20)/B20) -> 0.13397129 | M20: =IF(B20=0,0,K20/B20) -> 0.13397129
A21: Helpdesk | B21: =COUNTA('Helpdesk'!$A$2:$A$89) -> 88 | C21: =COUNTIF('Helpdesk'!$L$2:$L$89,"High") -> 28 | D21: =COUNTIF('Helpdesk'!$J$2:$J$89,"Positive") -> 40 | E21: =COUNTIF('Helpdesk'!$J$2:$J$89,"Negative") -> 3 | F21: =COUNTIF('Helpdesk'!$M$2:$M$89,"Automated (Linear Run)") -> 6 | G21: =COUNTIF('Helpdesk'!$M$2:$M$89,"Automated (Page Check)") -> 2 | H21: =COUNTIF('Helpdesk'!$M$2:$M$89,"Not Automated") -> 80 | I21: =COUNTIF('Helpdesk'!$M$2:$M$89,"Blocked") -> 0 | J21: =COUNTIF('Helpdesk'!$M$2:$M$89,"Out of Scope") -> 0 | K21: =COUNTIF('Helpdesk'!$O$2:$O$89,"Passed*") -> 8 | L21: =IF(B21=0,0,(F21+G21)/B21) -> 0.090909091 | M21: =IF(B21=0,0,K21/B21) -> 0.090909091
A22: Cross-Module E2E | B22: =COUNTA('Cross-Module E2E'!$A$2:$A$69) -> 68 | C22: =COUNTIF('Cross-Module E2E'!$L$2:$L$69,"High") -> 38 | D22: =COUNTIF('Cross-Module E2E'!$J$2:$J$69,"Positive") -> 0 | E22: =COUNTIF('Cross-Module E2E'!$J$2:$J$69,"Negative") -> 0 | F22: =COUNTIF('Cross-Module E2E'!$M$2:$M$69,"Automated (Linear Run)") -> 22 | G22: =COUNTIF('Cross-Module E2E'!$M$2:$M$69,"Automated (Page Check)") -> 0 | H22: =COUNTIF('Cross-Module E2E'!$M$2:$M$69,"Not Automated") -> 38 | I22: =COUNTIF('Cross-Module E2E'!$M$2:$M$69,"Blocked") -> 3 | J22: =COUNTIF('Cross-Module E2E'!$M$2:$M$69,"Out of Scope") -> 5 | K22: =COUNTIF('Cross-Module E2E'!$O$2:$O$69,"Passed*") -> 22 | L22: =IF(B22=0,0,(F22+G22)/B22) -> 0.32352941 | M22: =IF(B22=0,0,K22/B22) -> 0.32352941
A23: Non-Functional | B23: =COUNTA('Non-Functional'!$A$2:$A$104) -> 103 | C23: =COUNTIF('Non-Functional'!$L$2:$L$104,"High") -> 42 | D23: =COUNTIF('Non-Functional'!$J$2:$J$104,"Positive") -> 0 | E23: =COUNTIF('Non-Functional'!$J$2:$J$104,"Negative") -> 0 | F23: =COUNTIF('Non-Functional'!$M$2:$M$104,"Automated (Linear Run)") -> 3 | G23: =COUNTIF('Non-Functional'!$M$2:$M$104,"Automated (Page Check)") -> 1 | H23: =COUNTIF('Non-Functional'!$M$2:$M$104,"Not Automated") -> 96 | I23: =COUNTIF('Non-Functional'!$M$2:$M$104,"Blocked") -> 2 | J23: =COUNTIF('Non-Functional'!$M$2:$M$104,"Out of Scope") -> 1 | K23: =COUNTIF('Non-Functional'!$O$2:$O$104,"Passed*") -> 4 | L23: =IF(B23=0,0,(F23+G23)/B23) -> 0.038834951 | M23: =IF(B23=0,0,K23/B23) -> 0.038834951
A24: TOTAL | B24: =SUM(B11:B23) -> 2444 | C24: =SUM(C11:C23) -> 878 | D24: =SUM(D11:D23) -> 742 | E24: =SUM(E11:E23) -> 325 | F24: =SUM(F11:F23) -> 138 | G24: =SUM(G11:G23) -> 133 | H24: =SUM(H11:H23) -> 2058 | I24: =SUM(I11:I23) -> 57 | ... K24: =SUM(K11:K23) -> 271 | L24: =IF(B24=0,0,(F24+G24)/B24) -> 0.1108838 | M24: =IF(B24=0,0,K24/B24) -> 0.1108838
A26: Counts are live formulas over each module sheet — they update when you edit Automation / Execution Status. % Automated = (Linear Run + Page Check) ÷ Total.

Sheet Legend & How To Use
A1: COLUMNS
A2: Test ID | B2: TC-<MODULE>-<NNN>. Prefixes: LOG Login & Navigation · CHR Core HR · REC Recruitment · REF Referral · ONB Onboarding & Probation · ATT Attendance · LV Leave · PAY Payroll · EXT Resignation & Exit · ESS My Workspace · HD Helpdesk · E2E Cross-Module · NFR Non-Functional
A3: Page / Sub-module, Route | B3: Sidebar page the case belongs to and its URL path on hrms-test.progbiz.in
A4: Scenario / Description | B4: Feature under test and what this specific test case checks
A5: Test Steps | B5: Numbered actions to execute the test
A6: Steps to Reproduce | B6: The same path on one line — precondition → each step — ready to paste into a defect report if the case fails
A7: Severity | B7: Impact if the case fails. Critical = High priority core flow (Positive / E2E / Integration / Security) · Major = other High, or Medium core flow / Permission · Minor = other Medium, Low functional · Trivial = Low UI / Usability
A8: Type | B8: Positive · Negative · Boundary · Validation · UI · Permission · Integration · E2E · Security · Performance · Usability
A9: Priority | B9: High = core business flow / data integrity · Medium = important function · Low = cosmetic / rare
A10: Test Steps / Expected Result | B10: Numbered actions and the observable result that decides Pass/Fail
A11: Execution Status / Actual Result / Tested By | B11: For manual execution: set Execution Status (dropdown), note the Actual Result, and who/when
A13: AUTOMATION STATUS
A14: Automated (Linear Run) | B14: Exercised end-to-end by the Playwright linear run ("add data once" action on that page). Reference names the step, e.g. "Linear 013 Job Board — openingAndCandidate".
A15: Automated (Page Check) | B15: The linear run opens the page and checks it: not bounced to login, route exists, no application error, loading clears, heading shown, every list renders.
A16: Not Automated | B16: Valid case, not yet automated (manual execution). Payroll / Attendance / Resignation & Exit deep cases are owned by teammates.
A17: Blocked | B17: Cannot be automated now — needs an e-mailed link (candidate pre-boarding form), a device (attendance check-in), attendance records, or an unavailable role.
A18: Out of Scope | B18: Deliberately never automated (irreversible / financial / shared config): exit approval-clearance-F&F, payroll run finalisation & payments, statutory submissions, reward approval/payment, editing shared Payroll/Reward policy. Valid manual cases.
A20: RUNNING THE AUTOMATION
A21: Full run (headed) | B21: HEADED=1 npx playwright test -c hrms/playwright.config.js hrms/tests/00_linear --workers=1 --retries=0
A22: Read-only walk | B22: HRMS_LINEAR_READONLY=1 … (checks every page, adds nothing)
A23: One page / resume | B23: HRMS_PAGES="leave-approval,offer-list" · HRMS_FROM=52
A24: Evidence | B24: On any failure: reports/hrms-evidence/<run>/index.html — screenshots, recordings (incl. second user / candidate windows), whole-run video, trace.

Sheet Page Coverage
A1: # | B1: Section | C1: Page | D1: Route | E1: Linear-run check | F1: "Add data once" action | G1: Last run
A2: 1 | B2: Core HR | C2: Employee | D2: /employees | E2: Page check | F2: createRunEmployee | G2: Passed (19 Oct 2026)
A3: 2 | B3: Core HR | C3: Worker Directory | D3: /worker-directory | E3: Page check | F3: findRunEmployeeAndCompleteProfile | G3: Passed (19 Oct 2026)
A4: 3 | B4: Core HR | C4: Document Compliance | D4: /document-compliance | E4: Page check | F4: — | G4: Passed (19 Oct 2026)
A5: 4 | B5: Core HR | C5: HR Reminders | D5: /hrms/reminder-rules | E5: Page check | F5: — | G5: Passed (19 Oct 2026)
A6: 5 | B6: Core HR | C6: Employee Excel Import | D6: /upload-employee | E6: Page check | F6: — | G6: Passed (19 Oct 2026)
A7: 6 | B7: Core HR | C7: Letter Templates | D7: /letters/templates | E7: Page check | F7: createLetterTemplate | G7: Passed (19 Oct 2026)
A8: 7 | B8: Core HR | C8: Generate Letter | D8: /letters/generate | E8: Page check | F8: generateLetter | G8: Passed (19 Oct 2026)
A9: 8 | B9: Core HR | C9: Letterheads | D9: /letters/letterheads | E9: Page check | F9: — | G9: Passed (19 Oct 2026)
A10: 9 | B10: Core HR | C10: Merge Fields | D10: /letters/fields | E10: Page check | F10: — | G10: Passed (19 Oct 2026)
A11: 10 | B11: Core HR | C11: Approval Config | D11: /approval/config | E11: Page check | F11: — | G11: Passed (19 Oct 2026)
A12: 11 | B12: Core HR | C12: Duty Handover | D12: /employee-handover | E12: Page check | F12: createDutyHandover | G12: Passed (19 Oct 2026)
A13: 12 | B13: Recruitment | C13: Job Requisitions | D13: /requisition-list | E13: Page check | F13: raiseAndApproveRequisition | G13: Passed (19 Oct 2026)
... A129: 128 | B129: Helpdesk | C129: Helpdesk Dashboard | D129: /ess/helpdesk/admin | E129: Page check | F129: ticketLifecycle | G129: Passed (19 Oct 2026)

Sheet Login & Navigation
A1: Test ID | B1: Page / Sub-module | C1: Scenario | D1: Description | E1: Preconditions | F1: Test Data | G1: Test Steps | H1: Steps to Reproduce | I1: Expected Result | J1: Type | K1: Severity | L1: Priority | M1: Automation Status | N1: Automation Reference | O1: Execution Status | P1: Actual Result | Q1: Tested By / Date | R1: Route | S1: Remarks | T1: SRS Ref
A2: TC-LOG-001 | B2: Login | C2: Login page UI | D2: Login page renders all controls | E2: Logged out (fresh browser profile, no session) | G2: 1. Open https://hrms-test.progbiz.in/login 2. Observe the form | H2: Logged out (fresh browser profile, no session) → Open https://hrms-test.progbiz.in/login → Observe the form | I2: Company Code, User Name and Password inputs, a Sign In button, a Forgot password link and a Sign Up link are shown; no console/app error; password input is masked | J2: UI | K2: Major | L2: High | M2: Not Automated | O2: Not Executed | R2: /login
A3: TC-LOG-002 | B3: Login | C3: Login page UI | D3: Password characters are masked | E3: Logged out (fresh browser profile, no session) | F3: Password: Abc@1234 | G3: 1. Open /login 2. Type any text in Password | H3: Logged out (fresh browser profile, no session) → Open /login → Type any text in Password | I3: Password field is of type password and shows masked characters; value is never echoed in plain text | J3: Security | K3: Critical | L3: High | M3: Not Automated | O3: Not Executed | R3: /login
A4: TC-LOG-003 | B4: Login | C4: Login page UI | D4: Enter key submits the login form | E4: Logged out (fresh browser profile, no session) | F4: pbhrms / amit / <admin password> | G4: 1. Open /login 2. Fill Company Code, User Name, Password 3. Press Enter in the Password field | H4: Logged out (fresh browser profile, no session) → Open /login → Fill Company Code, User Name, Password → Press Enter in the Password field | I4: Form is submitted exactly as with the Sign In button and the user lands on Home | J4: Usability | K4: Minor | L4: Medium | M4: Not Automated | O4: Not Executed | R4: /login
A5: TC-LOG-004 | B5: Login | C5: Valid login | D5: Admin signs in with valid company code, user name and password | E5: Logged out (fresh browser profile, no session); admin account amit is active | F5: Company Code: pbhrms; User Name: amit | G5: 1. Open /login 2. Enter Company Code 3. Enter User Name 4. Enter Password 5. Click Sign In | H5: Logged out (fresh browser profile, no session); admin account amit is active → Open /login → Enter Company Code → Enter User Name → Enter Password → Click Sign In | I5: User leaves /login and lands on Home (/home); sidebar shows the HRMS menu; header shows Amit Kumar Shaji | J5: Positive | K5: Critical | L5: High | M5: Automated (Linear Run) | N5: Linear run global-setup — HrmsLoginPage.login (admin session reused by all 128 steps) | O5: Passed (19 Oct 2026) | R5: /login
A6: TC-LOG-005 | B6: Login | C6: Valid login | D6: Employee signs in with the initial password = employee code | E6: Logged out (fresh browser profile, no session); an employee was created in Core HR with Login Username set and Can Login ticked | F6: Username: as set on create; Password: employee code (e.g. pbhrms0305) | G6: 1. Open /login 2. Enter Company Code pbhrms 3. Enter the employee's Login Username 4. Enter the employee code as Password 5. Click Sign In | H6: Logged out (fresh browser profile, no session); an employee was created in Core HR with Login Username set and Can Login ticked → Open /login → Enter Company Code pbhrms → Enter the employee's Login Username → Enter the employee code as Password → Click Sign In | I6: Login succeeds; employee lands on Home / My Workspace with only the menus their role allows | J6: Positive | K6: Critical | L6: High | M6: Automated (Linear Run) | N6: Linear 056 Leave Approval — employeeAppliesManagerApproves (withUser signs in as the run employee) | O6: Passed (19 Oct 2026) | R6: /login
A7: TC-LOG-006 | B7: Login | C7: Valid login | D7: Team Lead user signs in | E7: Logged out (fresh browser profile, no session); a user with access role Team Lead exists | G7: 1. Open /login 2. Enter pbhrms, the Team Lead user name and password 3. Click Sign In | H7: Logged out (fresh browser profile, no session); a user with access role Team Lead exists → Open /login → Enter pbhrms, the Team Lead user name and password → Click Sign In | I7: Login succeeds; Team Lead sees My Workspace plus the team/approval menus their role grants | J7: Positive | K7: Major | L7: Medium | M7: Not Automated | O7: Not Executed | R7: /login
A8: TC-LOG-007 | B8: Login | C8: Valid login | D8: Login completes within acceptable time | E8: Logged out (fresh browser profile, no session) | G8: 1. Open /login 2. Sign in with valid admin credentials 3. Measure time until Home is fully rendered | H8: Logged out (fresh browser profile, no session) → Open /login → Sign in with valid admin credentials → Measure time until Home is fully rendered | I8: Home page is interactive within 5 seconds on a normal connection | J8: Performance | K8: Minor | L8: Medium | M8: Not Automated | O8: Not Executed | R8: /login
A9: TC-LOG-008 | B9: Login | C9: Invalid login | D9: Wrong password is rejected | E9: Logged out (fresh browser profile, no session) | F9: Password: WrongPass@1 | G9: 1. Open /login 2. Enter pbhrms / amit 3. Enter an incorrect password 4. Click Sign In | H9: Logged out (fresh browser profile, no session) → Open /login → Enter pbhrms / amit → Enter an incorrect password → Click Sign In | I9: Login refused with an error message (e.g. invalid credentials); user stays on /login; password field cleared or kept masked | J9: Negative | K9: Major | L9: High | M9: Not Automated | O9: Not Executed | R9: /login
A10: TC-LOG-009 | B10: Login | C10: Invalid login | D10: Unknown user name is rejected | E10: Logged out (fresh browser profile, no session) | F10: User Name: no.such.user | G10: 1. Open /login 2. Enter pbhrms 3. Enter user name that does not exist 4. Enter any password 5. Click Sign In | H10: Logged out (fresh browser profile, no session) → Open /login → Enter pbhrms → Enter user name that does not exist → Enter any password → Click Sign In | I10: Login refused; error message does not reveal whether the user name exists | J10: Negative | K10: Major | L10: High | M10: Not Automated | O10: Not Executed | R10: /login
A11: TC-LOG-010 | B11: Login | C11: Invalid login | D11: Wrong company code is rejected | E11: Logged out (fresh browser profile, no session) | F11: Company Code: pbhrmsX | G11: 1. Open /login 2. Enter an invalid company code 3. Enter valid user name and password 4. Click Sign In | H11: Logged out (fresh browser profile, no session) → Open /login → Enter an invalid company code → Enter valid user name and password → Click Sign In | I11: Login refused with an invalid company / credentials message; no session created | J11: Negative | K11: Major | L11: High | M11: Not Automated | O11: Not Executed | R11: /login
A12: TC-LOG-011 | B12: Login | C12: Invalid login | D12: Valid user name with another tenant's company code is rejected | E12: Logged out (fresh browser profile, no session); a second tenant code exists (e.g. progbiz) | G12: 1. Open /login 2. Enter the other tenant's company code 3. Enter amit and the pbhrms password 4. Click Sign In | H12: Logged out (fresh browser profile, no session); a second tenant code exists (e.g. progbiz) → Open /login → Enter the other tenant's company code → Enter amit and the pbhrms password → Click Sign In | I12: Login refused; user cannot reach pbhrms data through another tenant code (tenant isolation) | J12: Security | K12: Critical | L12: High | M12: Not Automated | O12: Not Executed | R12: /login
A13: TC-LOG-012 | B13: Login | C13: Mandatory fields | D13: Company Code blank shows validation | E13: Logged out (fresh browser profile, no session) | G13: 1. Open /login 2. Leave Company Code empty 3. Fill User Name and Password 4. Click Sign In | H13: Logged out (fresh browser profile, no session) → Open /login → Leave Company Code empty → Fill User Name and Password → Click Sign In | I13: Inline/required validation on Company Code; no login request is sent | J13: Validation | K13: Major | L13: High | M13: Not Automated | O13: Not Executed | R13: /login
A14: TC-LOG-013 | B14: Login | C14: Mandatory fields | D14: User Name blank shows validation | E14: Logged out (fresh browser profile, no session) | G14: 1. Open /login 2. Fill Company Code 3. Leave User Name empty 4. Fill Password 5. Click Sign In | H14: Logged out (fresh browser profile, no session) → Open /login → Fill Company Code → Leave User Name empty → Fill Password → Click Sign In | I14: Required validation on User Name; user stays on /login | J14: Validation | K14: Major | L14: High | M14: Not Automated | O14: Not Executed | R14: /login
A15: TC-LOG-014 | B15: Login | C15: Mandatory fields | D15: Password blank shows validation | E15: Logged out (fresh browser profile, no session) | G15: 1. Open /login 2. Fill Company Code and User Name 3. Leave Password empty 4. Click Sign In | H15: Logged out (fresh browser profile, no session) → Open /login → Fill Company Code and User Name → Leave Password empty → Click Sign In | I15: Required validation on Password; user stays on /login | J15: Validation | K15: Major | L15: High | M15: Not Automated | O15: Not Executed | R15: /login
A16: TC-LOG-015 | B16: Login | C16: Mandatory fields | D16: All fields blank shows validation for each | E16: Logged out (fresh browser profile, no session) | G16: 1. Open /login 2. Click Sign In without filling anything | H16: Logged out (fresh browser profile, no session) → Open /login → Click Sign In without filling anything | I16: All three fields flagged as required; no request sent; no server error | J16: Validation | K16: Minor | L16: Medium | M16: Not Automated | O16: Not Executed | R16: /login
A17: TC-LOG-016 | B17: Login | C17: Input handling | D17: Company code is case-insensitive | E17: Logged out (fresh browser profile, no session) | F17: Company Code: PBHRMS | G17: 1. Open /login 2. Enter PBHRMS (upper case) with valid user name and password 3. Click Sign In | H17: Logged out (fresh browser profile, no session) → Open /login → Enter PBHRMS (upper case) with valid user name and password → Click Sign In | I17: Login behaves consistently — accepted as the same tenant (case-insensitive) or refused with a clear message; never an application error | J17: Boundary | K17: Minor | L17: Low | M17: Not Automated | O17: Not Executed | R17: /login
A18: TC-LOG-017 | B18: Login | C18: Input handling | D18: Password is case-sensitive | E18: Logged out (fresh browser profile, no session) | G18: 1. Open /login 2. Enter valid company code and user name 3. Enter the correct password with letter case inverted 4. Click Sign In | H18: Logged out (fresh browser profile, no session) → Open /login → Enter valid company code and user name → Enter the correct password with letter case inverted → Click Sign In | I18: Login refused — password comparison is case-sensitive | J18: Security | K18: Critical | L18: High | M18: Not Automated | O18: Not Executed | R18: /login
A19: TC-LOG-018 | B19: Login | C19: Input handling | D19: Leading/trailing spaces in user name and company code | E19: Logged out (fresh browser profile, no session) | G19: 1. Open /login 2. Enter " pbhrms " and " amit " with surrounding spaces 3. Enter correct password 4. Click Sign In | H19: Logged out (fresh browser profile, no session) → Open /login → Enter " pbhrms " and " amit " with surrounding spaces → Enter correct password → Click Sign In | I19: Spaces are trimmed and login succeeds, or a clear invalid-credentials message is shown; no application error | J19: Boundary | K19: Minor | L19: Medium | M19: Not Automated | O19: Not Executed | R19: /login
A20: TC-LOG-019 | B20: Login | C20: Security | D20: SQL injection in User Name is not executed | E20: Logged out (fresh browser profile, no session) | F20: User Name: ' OR 1=1 -- | G20: 1. Open /login 2. Enter pbhrms 3. Enter ' OR 1=1 -- as User Name 4. Enter any password 5. Click Sign In | H20: Logged out (fresh browser profile, no session) → Open /login → Enter pbhrms → Enter ' OR 1=1 -- as User Name → Enter any password → Click Sign In | I20: Login refused as invalid credentials; no database error or internal detail is shown | J20: Security | K20: Critical | L20: High | M20: Not Automated | O20: Not Executed | R20: /login
A21: TC-LOG-020 | B21: Login | C21: Security | D21: Repeated failed logins are throttled or locked | E21: Logged out (fresh browser profile, no session) | G21: 1. Open /login 2. Attempt 10 consecutive logins for amit with a wrong password 3. Then try the correct password | H21: Logged out (fresh browser profile, no session) → Open /login → Attempt 10 consecutive logins for amit with a wrong password → Then try the correct password | I21: After repeated failures the account/IP is throttled or temporarily locked (or a delay is enforced); behaviour is documented and no unlimited brute force is possible | J21: Security | K21: Major | L21: Medium | M21: Not Automated | O21: Not Executed | R21: /login | S21: Lockout threshold is not defined in the SRS — record actual behaviour; run only against a disposable test user
A22: TC-LOG-021 | B22: Login | C22: Security | D22: Credentials are never sent in the URL | E22: Logged out (fresh browser profile, no session) | G22: 1. Open /login with browser DevTools Network tab 2. Sign in 3. Inspect the login request and resulting URL | H22: Logged out (fresh browser profile, no session) → Open /login with browser DevTools Network tab → Sign in → Inspect the login request and resulting URL | I22: Login is a POST over HTTPS; company code, user name and password never appear in the URL or query string | J22: Security | K22: Critical | L22: High | M22: Not Automated | O22: Not Executed | R22: /login
A23: TC-LOG-022 | B23: Login | C23: Account state | D23: Employee with Can Login unticked cannot sign in | E23: An employee exists whose Can Login checkbox is unticked on the employee form | G23: 1. Open /login 2. Enter pbhrms, that employee's user name and employee-code password 3. Click Sign In | H23: An employee exists whose Can Login checkbox is unticked on the employee form → Open /login → Enter pbhrms, that employee's user name and employee-code password → Click Sign In | I23: Login refused (login disabled / invalid credentials); no session created | J23: Permission | K23: Major | L23: High | M23: Not Automated | O23: Not Executed | R23: /login
A24: TC-LOG-023 | B24: Login | C24: Account state | D24: Exited / archived employee cannot sign in | E24: An employee whose exit is completed (status Archived/Resigned) exists with a login | G24: 1. Open /login 2. Enter that employee's credentials 3. Click Sign In | H24: An employee whose exit is completed (status Archived/Resigned) exists with a login → Open /login → Enter that employee's credentials → Click Sign In | I24: Login refused; former employee cannot access the app | J24: Permission | K24: Major | L24: High | M24: Not Automated | O24: Not Executed | R24: /login
A25: TC-LOG-024 | B25: Forgot Password | C25: Forgot password | D25: Forgot password link opens the reset form | E25: Logged out (fresh browser profile, no session) | G25: 1. Open /login 2. Click Forgot password | H25: Logged out (fresh browser profile, no session) → Open /login → Click Forgot password | I25: Password reset form opens with the identifying fields (company code / user name or e-mail) and a submit button, plus a way back to Sign In | J25: UI | K25: Major | L25: High | M25: Not Automated | O25: Not Executed | R25: /login
A26: TC-LOG-025 | B26: Forgot Password | C26: Forgot password | D26: Reset request for a registered user | E26: Logged out (fresh browser profile, no session); a test employee with a valid @example.com e-mail exists | F26: User: run employee (e.g. rohan.varghese@example.com) | G26: 1. Open Forgot password 2. Enter the company code and the test user's user name / e-mail 3. Submit | H26: Logged out (fresh browser profile, no session); a test employee with a valid @example.com e-mail exists → Open Forgot password → Enter the company code and the test user's user name / e-mail → Submit | I26: Confirmation message that reset instructions were sent; reset e-mail queued to the user's registered address | J26: Positive | K26: Critical | L26: High | M26: Not Automated | O26: Not Executed | R26: /login
A27: TC-LOG-026 | B27: Forgot Password | C27: Forgot password | D27: Reset request for an unknown user does not reveal existence | E27: Logged out (fresh browser profile, no session) | F27: nobody@example.com | G27: 1. Open Forgot password 2. Enter a user name / e-mail that does not exist 3. Submit | H27: Logged out (fresh browser profile, no session) → Open Forgot password → Enter a user name / e-mail that does not exist → Submit | I27: Generic message (same as for a valid user) or a neutral error; the response does not confirm whether the account exists | J27: Security | K27: Major | L27: Medium | M27: Not Automated | O27: Not Executed | R27: /login
A28: TC-LOG-027 | B28: Forgot Password | C28: Forgot password | D28: Reset form mandatory validation | E28: Logged out (fresh browser profile, no session) | G28: 1. Open Forgot password 2. Submit with all fields empty | H28: Logged out (fresh browser profile, no session) → Open Forgot password → Submit with all fields empty | I28: Required-field validation shown; no request sent | J28: Validation | K28: Minor | L28: Medium | M28: Not Automated | O28: Not Executed | R28: /login
A29: TC-LOG-028 | B29: Forgot Password | C29: Forgot password | D29: Reset link sets a new password and old one stops working | E29: A reset e-mail has been received for a test user | G29: 1. Open the reset link from the e-mail 2. Enter and confirm a new password 3. Submit 4. Sign in with the new password 5. Try the old password | H29: A reset e-mail has been received for a test user → Open the reset link from the e-mail → Enter and confirm a new password → Submit → Sign in with the new password → Try the old password | I29: New password works; old password is rejected; reset link cannot be reused | J29: E2E | K29: Critical | L29: High | M29: Blocked | O29: Not Executed | R29: /login | S29: Needs the e-mailed reset link, which automation cannot receive
A30: TC-LOG-029 | B30: Forgot Password | C30: Forgot password | D30: Expired or reused reset link is refused | E30: A reset link has already been used or has expired | G30: 1. Open the used/expired reset link | H30: A reset link has already been used or has expired → Open the used/expired reset link | I30: Page states the link is invalid or expired and offers to request a new one | J30: Negative | K30: Minor | L30: Medium | M30: Blocked | O30: Not Executed | R30: /login | S30: Needs the e-mailed reset link
A31: TC-LOG-030 | B31: Sign Up | C31: Sign up | D31: Sign Up link opens the registration form | E31: Logged out (fresh browser profile, no session) | G31: 1. Open /login 2. Click Sign Up | H31: Logged out (fresh browser profile, no session) → Open /login → Click Sign Up | I31: Registration form opens with its fields and a submit button; nothing is created until submitted | J31: UI | K31: Minor | L31: Medium | M31: Not Automated | O31: Not Executed | R31: /login | S31: Do not submit on the shared test tenant — creates a new organisation/account
A32: TC-LOG-031 | B32: Sign Up | C32: Sign up | D32: Sign Up mandatory-field validation | E32: Logged out (fresh browser profile, no session) | G32: 1. Open Sign Up 2. Click submit with all fields empty | H32: Logged out (fresh browser profile, no session) → Open Sign Up → Click submit with all fields empty | I32: Each required field is flagged; no account is created | J32: Validation | K32: Minor | L32: Low | M32: Not Automated | O32: Not Executed | R32: /login
A33: TC-LOG-032 | B33: Session & Logout | C33: Logout | D33: Logout from the profile menu ends the session | E33: Logged in as HRMS admin amit (Amit Kumar Shaji, role HRMS / Administrator) | G33: 1. Click the profile avatar in the header 2. Click Logout | H33: Logged in as HRMS admin amit (Amit Kumar Shaji, role HRMS / Administrator) → Click the profile avatar in the header → Click Logout | I33: User is returned to /login; session cookie/token is cleared | J33: Positive | K33: Critical | L33: High | M33: Not Automated | O33: Not Executed
A34: TC-LOG-033 | B34: Session & Logout | C34: Logout | D34: Browser Back after logout does not show protected data | E34: Logged in as HRMS admin amit (Amit Kumar Shaji, role HRMS / Administrator) | G34: 1. Open /employees 2. Logout 3. Press browser Back | H34: Logged in as HRMS admin amit (Amit Kumar Shaji, role HRMS / Administrator) → Open /employees → Logout → Press browser Back | I34: User stays on / is redirected to /login; the employee list is not displayed from cache with live data | J34: Security | K34: Critical | L34: High | M34: Not Automated | O34: Not Executed
A35: TC-LOG-034 | B35: Session & Logout | C35: Logout | D35: Protected URL after logout redirects to login | E35: Logged in as HRMS admin amit (Amit Kumar Shaji, role HRMS / Administrator) | G35: 1. Logout 2. Type /employees in the address bar | H35: Logged in as HRMS admin amit (Amit Kumar Shaji, role HRMS / Administrator) → Logout → Type /employees in the address bar | I35: Redirected to /login; no data shown | J35: Security | K35: Critical | L35: High | M35: Not Automated | O35: Not Executed
A36: TC-LOG-035 | B36: Session & Logout | C36: Logout | D36: Logout in one tab invalidates the other tab | E36: Logged in as HRMS admin amit (Amit Kumar Shaji, role HRMS / Administrator) in two tabs | G36: 1. Open /employees in tab A and /leave-approval in tab B 2. Logout in tab A 3. Click any menu link in tab B | H36: Logged in as HRMS admin amit (Amit Kumar Shaji, role HRMS / Administrator) in two tabs → Open /employees in tab A and /leave-approval in tab B → Logout in tab A → Click any menu link in tab B | I36: Tab B is redirected to /login on its next request | J36: Security | K36: Major | L36: Medium | M36: Not Automated | O36: Not Executed
A37: TC-LOG-036 | B37: Session & Logout | C37: Session | D37: Session survives a page refresh | E37: Logged in as HRMS admin amit (Amit Kumar Shaji, role HRMS / Administrator) | G37: 1. Open /letters/templates 2. Press F5 | H37: Logged in as HRMS admin amit (Amit Kumar Shaji, role HRMS / Administrator) → Open /letters/templates → Press F5 | I37: User stays signed in on the same page; data reloads; no login prompt | J37: Positive | K37: Critical | L37: High | M37: Not Automated | O37: Not Executed
A38: TC-LOG-037 | B38: Session & Logout | C38: Session | D38: Two different users in separate browser contexts | E38: Logged in as HRMS admin amit (Amit Kumar Shaji, role HRMS / Administrator); a test employee login exists | G38: 1. Keep admin signed in in the main window 2. Open an incognito/second context 3. Sign in as the test employee 4. Act in both | H38: Logged in as HRMS admin amit (Amit Kumar Shaji, role HRMS / Administrator); a test employee login exists → Keep admin signed in in the main window → Open an incognito/second context → Sign in as the test employee → Act in both | I38: Each window keeps its own user; actions are attributed to the correct user; no session bleed | J38: Positive | K38: Critical | L38: High | M38: Automated (Linear Run) | N38: Linear 056 Leave Approval — employeeAppliesManagerApproves (withUser signs in as the run employee) | O38: Passed (19 Oct 2026)
A39: TC-LOG-038 | B39: Session & Logout | C39: Session expiry | D39: Idle session expires and next action goes to login | E39: Logged in as HRMS admin amit (Amit Kumar Shaji, role HRMS / Administrator) | G39: 1. Sign in 2. Leave the browser idle beyond the token lifetime 3. Click a menu item | H39: Logged in as HRMS admin amit (Amit Kumar Shaji, role HRMS / Administrator) → Sign in → Leave the browser idle beyond the token lifetime → Click a menu item | I39: If the token refresh fails the user is redirected to /login; no partial page or false success | J39: Security | K39: Critical | L39: High | M39: Not Automated | O39: Not Executed | T39: Core HR SRS §10.4
A40: TC-LOG-039 | B40: Session & Logout | C40: Session expiry | D40: Active user is not logged out mid-work | E40: Logged in as HRMS admin amit (Amit Kumar Shaji, role HRMS / Administrator) | G40: 1. Keep using the app (navigate every few minutes) past the access-token lifetime | H40: Logged in as HRMS admin amit (Amit Kumar Shaji, role HRMS / Administrator) → Keep using the app (navigate every few minutes) past the access-token lifetime | I40: Expired access token is refreshed transparently; the user is not interrupted | J40: Positive | K40: Major | L40: Medium | M40: Not Automated | O40: Not Executed | T40: Core HR SRS §10.4
...

Sheet Core HR
A1: Test ID | B1: Page / Sub-module | C1: Scenario | D1: Description | E1: Preconditions | F1: Test Data | G1: Test Steps | H1: Steps to Reproduce | I1: Expected Result | J1: Type | K1: Severity | L1: Priority | M1: Automation Status | N1: Automation Reference | O1: Execution Status | P1: Actual Result | Q1: Tested By / Date | R1: Route | S1: Remarks | T1: SRS Ref
A2: TC-CHR-001 | B2: Employee | C2: Page load | D2: Employee list page opens and renders | E2: Logged in as HRMS admin amit (Amit Kumar Shaji, role HRMS / Administrator) | G2: 1. Open HRMS > Core HR > Employee | H2: Logged in as HRMS admin amit (Amit Kumar Shaji, role HRMS / Administrator) → Open HRMS > Core HR > Employee | I2: Heading shown; grid with columns Sl.No, Employee Code, Employee Name, Department Name, Designation, Status, Actions; New Employee button; loading clears; no app error | J2: UI | K2: Major | L2: High | M2: Automated (Page Check) | N2: Linear 001 Employee — page check | O2: Passed (19 Oct 2026) | R2: /employees
A3: TC-CHR-002 | B3: Employee | C3: List | D3: Default sort is Employee Code ascending | E3: Logged in as HRMS admin amit (Amit Kumar Shaji, role HRMS / Administrator) | G3: 1. Open Employee list 2. Observe the order of the Employee Code column | H3: Logged in as HRMS admin amit (Amit Kumar Shaji, role HRMS / Administrator) → Open Employee list → Observe the order of the Employee Code column | I3: Rows are sorted by Employee Code ascending with a sort indicator on that column | J3: Positive | K3: Minor | L3: Low | M3: Not Automated | O3: Not Executed | R3: /employees | T3: §4.2
A4: TC-CHR-003 | B4: Employee | C4: List | D4: Sort by each sortable column | E4: Logged in as HRMS admin amit (Amit Kumar Shaji, role HRMS / Administrator) | G4: 1. Click Employee Code header 2. Click again 3. Repeat for Employee Name, Department Name, Designation | H4: Logged in as HRMS admin amit (Amit Kumar Shaji, role HRMS / Administrator) → Click Employee Code header → Click again → Repeat for Employee Name, Department Name, Designation | I4: Each click toggles ascending/descending; sort indicator updates; data re-ordered server-side | J4: Positive | K4: Major | L4: Medium | M4: Not Automated | O4: Not Executed | R4: /employees | T4: §4.2
A5: TC-CHR-004 | B5: Employee | C5: Search | D5: Quick search by employee name | E5: Logged in as HRMS admin amit (Amit Kumar Shaji, role HRMS / Administrator); run employee exists | F5: e.g. "Varghese" | G5: 1. Type part of the run employee's name in the quick-search box | H5: Logged in as HRMS admin amit (Amit Kumar Shaji, role HRMS / Administrator); run employee exists → Type part of the run employee's name in the quick-search box | I5: Grid shows only matching employees; count updates | J5: Positive | K5: Critical | L5: High | M5: Not Automated | O5: Not Executed | R5: /employees | T5: FR-CH-023
A6: TC-CHR-005 | B6: Employee | C6: Search | D6: Quick search by employee code | E6: Logged in as HRMS admin amit (Amit Kumar Shaji, role HRMS / Administrator) | F6: e.g. pbhrms0305 | G6: 1. Type a full employee code in quick search | H6: Logged in as HRMS admin amit (Amit Kumar Shaji, role HRMS / Administrator) → Type a full employee code in quick search | I6: Exactly the employee with that code is listed | J6: Positive | K6: Critical | L6: High | M6: Automated (Linear Run) | N6: Linear 001 Employee — createRunEmployee | O6: Passed (19 Oct 2026) | R6: /employees | T6: FR-CH-023
A7: TC-CHR-006 | B7: Employee | C7: Search | D7: Quick search by phone and by e-mail | E7: Logged in as HRMS admin amit (Amit Kumar Shaji, role HRMS / Administrator) | G7: 1. Search the run employee's phone 2. Clear 3. Search their e-mail | H7: Logged in as HRMS admin amit (Amit Kumar Shaji, role HRMS / Administrator) → Search the run employee's phone → Clear → Search their e-mail | I7: Both searches return the run employee | J7: Positive | K7: Major | L7: Medium | M7: Not Automated | O7: Not Executed | R7: /employees | T7: FR-CH-023
A8: TC-CHR-007 | B8: Employee | C8: Search | D8: Quick search with no match | E8: Logged in as HRMS admin amit (Amit Kumar Shaji, role HRMS / Administrator) | G8: 1. Type "zzqqxx" in quick search | H8: Logged in as HRMS admin amit (Amit Kumar Shaji, role HRMS / Administrator) → Type "zzqqxx" in quick search | I8: Empty-state row / "no records" message; no error | J8: Negative | K8: Minor | L8: Low | M8: Not Automated | O8: Not Executed | R8: /employees
A9: TC-CHR-008 | B9: Employee | C9: Filter | D9: Advanced filter drawer narrows the list | E9: Logged in as HRMS admin amit (Amit Kumar Shaji, role HRMS / Administrator) | G9: 1. Open the filter drawer 2. Choose Branch Main Branch and Designation SOFTWARE TESTER 3. Click Apply Filters | H9: Logged in as HRMS admin amit (Amit Kumar Shaji, role HRMS / Administrator) → Open the filter drawer → Choose Branch Main Branch and Designation SOFTWARE TESTER → Click Apply Filters | I9: Only matching employees listed; badge shows 2 active filters | J9: Positive | K9: Major | L9: Medium | M9: Not Automated | O9: Not Executed | R9: /employees | T9: FR-CH-024
A10: TC-CHR-009 | B10: Employee | C10: Filter | D10: Closing the drawer without Apply changes nothing | E10: Logged in as HRMS admin amit (Amit Kumar Shaji, role HRMS / Administrator) | G10: 1. Open the filter drawer 2. Change Department 3. Close the drawer without Apply | H10: Logged in as HRMS admin amit (Amit Kumar Shaji, role HRMS / Administrator) → Open the filter drawer → Change Department → Close the drawer without Apply | I10: Grid and active-filter badge unchanged | J10: Positive | K10: Minor | L10: Low | M10: Not Automated | O10: Not Executed | R10: /employees | T10: FR-CH-024
A11: TC-CHR-010 | B11: Employee | C11: Filter | D11: Reset clears all drawer filters | E11: Logged in as HRMS admin amit (Amit Kumar Shaji, role HRMS / Administrator); filters applied | G11: 1. Open the filter drawer 2. Click Reset | H11: Logged in as HRMS admin amit (Amit Kumar Shaji, role HRMS / Administrator); filters applied → Open the filter drawer → Click Reset | I11: All narrowing filters cleared; badge disappears; full list shown | J11: Positive | K11: Minor | L11: Low | M11: Not Automated | O11: Not Executed | R11: /employees
A12: TC-CHR-011 | B12: Employee | C12: Filter | D12: Joined-from after joined-to | E12: Logged in as HRMS admin amit (Amit Kumar Shaji, role HRMS / Administrator) | G12: 1. Open filter drawer 2. Set Joined From 2026-10-01 and Joined To 2026-09-01 3. Apply | H12: Logged in as HRMS admin amit (Amit Kumar Shaji, role HRMS / Administrator) → Open filter drawer → Set Joined From 2026-10-01 and Joined To 2026-09-01 → Apply | I12: Validation message or empty result; no server error | J12: Negative | K12: Minor | L12: Low | M12: Not Automated | O12: Not Executed | R12: /employees
A13: TC-CHR-012 | B13: Employee | C13: Archived | D13: Archived employees hidden by default and shown with Include archived | E13: Logged in as HRMS admin amit (Amit Kumar Shaji, role HRMS / Administrator); an archived (exited) employee exists | G13: 1. Open Employee list 2. Search the archived employee 3. Switch on Include archived | H13: Logged in as HRMS admin amit (Amit Kumar Shaji, role HRMS / Administrator); an archived (exited) employee exists → Open Employee list → Search the archived employee → Switch on Include archived | I13: Not found by default; listed once Include archived is on; the toggle is not counted in the filter badge | J13: Positive | K13: Major | L13: Medium | M13: Not Automated | O13: Not Executed | R13: /employees | T13: FR-CH-025
A14: TC-CHR-013 | B14: Employee | C14: Paging | D14: Pagination and page size | E14: Logged in as HRMS admin amit (Amit Kumar Shaji, role HRMS / Administrator); more than 10 employees | G14: 1. Change page size to 25 2. Go to page 2 3. Run a search | H14: Logged in as HRMS admin amit (Amit Kumar Shaji, role HRMS / Administrator); more than 10 employees → Change page size to 25 → Go to page 2 → Run a search | I14: Page size applies and is preserved across the search; pager shows total count and page index | J14: Positive | K14: Major | L14: Medium | M14: Not Automated | O14: Not Executed | R14: /employees | T14: FR-CH-021
A15: TC-CHR-014 | B15: Employee | C15: Row actions | D15: Edit icon opens the employee Edit form | E15: Logged in as HRMS admin amit (Amit Kumar Shaji, role HRMS / Administrator) | G15: 1. Click the pencil icon on the run employee row | H15: Logged in as HRMS admin amit (Amit Kumar Shaji, role HRMS / Administrator) → Click the pencil icon on the run employee row | I15: Navigates to /employee/<guid> with the form pre-filled | J15: Positive | K15: Critical | L15: High | M15: Not Automated | O15: Not Executed | R15: /employees
A16: TC-CHR-015 | B16: Employee | C16: Row actions | D16: Clicking the employee name opens the read-only profile | E16: Logged in as HRMS admin amit (Amit Kumar Shaji, role HRMS / Administrator) | G16: 1. Click the run employee's name/view action | H16: Logged in as HRMS admin amit (Amit Kumar Shaji, role HRMS / Administrator) → Click the run employee's name/view action | I16: Navigates to /employee-view/<guid> | J16: Positive | K16: Major | L16: Medium | M16: Not Automated | O16: Not Executed | R16: /employees
A17: TC-CHR-016 | B17: Employee | C17: Row actions | D17: Delete asks for confirmation; Cancel keeps the employee | E17: Logged in as HRMS admin amit (Amit Kumar Shaji, role HRMS / Administrator); a disposable test employee exists | G17: 1. Click the delete icon on the test employee row 2. Click No/Cancel in the confirmation | H17: Logged in as HRMS admin amit (Amit Kumar Shaji, role HRMS / Administrator); a disposable test employee exists → Click the delete icon on the test employee row → Click No/Cancel in the confirmation | I17: Confirmation names the employee; on Cancel nothing is deleted and the row remains | J17: Negative | K17: Major | L17: High | M17: Not Automated | O17: Not Executed | R17: /employees
A18: TC-CHR-017 | B18: Employee | C18: Row actions | D18: Delete a disposable employee after confirmation | E18: Logged in as HRMS admin amit (Amit Kumar Shaji, role HRMS / Administrator); a disposable test employee with no transactions | G18: 1. Click delete on the test employee 2. Confirm Yes | H18: Logged in as HRMS admin amit (Amit Kumar Shaji, role HRMS / Administrator); a disposable test employee with no transactions → Click delete on the test employee → Confirm Yes | I18: Success message; employee no longer listed; their login no longer works | J18: Positive | K18: Major | L18: Medium | M18: Not Automated | O18: Not Executed | R18: /employees | S18: Use only a throwaway employee created for this test
A19: TC-CHR-018 | B19: Employee | C19: Row actions | D19: Delete of an employee with transactions is refused or soft | E19: Logged in as HRMS admin amit (Amit Kumar Shaji, role HRMS / Administrator); employee with leave/payroll history | G19: 1. Click delete on that employee 2. Confirm | H19: Logged in as HRMS admin amit (Amit Kumar Shaji, role HRMS / Administrator); employee with leave/payroll history → Click delete on that employee → Confirm | I19: Delete is refused with a clear message, or the employee is soft-deleted so history in Leave/Payroll stays intact | J19: Negative | K19: Minor | L19: Medium | M19: Not Automated | O19: Not Executed | R19: /employees
A20: TC-CHR-019 | B20: Employee | C20: Status badge | D20: Status column reflects lifecycle status | E20: Logged in as HRMS admin amit (Amit Kumar Shaji, role HRMS / Administrator); employees in Active and Pre-Employee status | G20: 1. Open the list 2. Compare the Status badge with each employee's status | H20: Logged in as HRMS admin amit (Amit Kumar Shaji, role HRMS / Administrator); employees in Active and Pre-Employee status → Open the list → Compare the Status badge with each employee's status | I20: Active and Pre-Employee badges are shown correctly with distinct colours | J20: UI | K20: Trivial | L20: Low | M20: Not Automated | O20: Not Executed | R20: /employees
A21: TC-CHR-020 | B21: Employee | C21: Create employee | D21: Create an employee with all mandatory fields | E21: Logged in as HRMS admin amit (Amit Kumar Shaji, role HRMS / Administrator); on Core HR > Employee, New Employee form (/employee) open | F21: Role Group Staff, User Level Team Member, Reports To Amit Kumar Shaji, Designation SOFTWARE TESTER, Branch Main Branch, First Name, Last Name, Display Name, Date of Birth, Gender, Phone, Email, Employment Type Full Time Employee, Status Active, Joining Date; Name: realistic person e.g. Rohan Varghese; Email: rohan.varghese@example.com | G21: 1. Choose Role Group and User Level 2. Pick Reports To 3. Fill Designation, Branch, names, Date of Birth, Gender, Phone (Same as Phone ON), Email 4. Choose Work Location, Employment Type, Status, Joining Date 5. Fill present address, tick Same as Present 6. Set Login Username, keep Can Login ticked 7. Save | H21: Logged in as HRMS admin amit (Amit Kumar Shaji, role HRMS / Administrator); on Core HR > Employee, New Employee form (/employee) open → Choose Role Group and User Level → Pick Reports To → Fill Designation, Branch, names, Date of Birth, Gender, Phone (Same as Phone ON), Email → Choose Work Location, Employment Type, Status, Joining Date → Fill present address, tick Same as Present → Set Login Username, keep Can Login ticked → Save | I21: Success / redirect to /employees; employee listed with a new auto-generated code (e.g. pbhrms0xxx); "Login created for <name>" dialog shows username and password = code | J21: Positive | K21: Critical | L21: High | M21: Automated (Linear Run) | N21: Linear 001 Employee — createRunEmployee | O21: Passed (19 Oct 2026) | R21: /employee
A22: TC-CHR-021 | B22: Employee | C22: Create employee | D22: Employee Code is auto-generated and read-only | E22: Logged in as HRMS admin amit (Amit Kumar Shaji, role HRMS / Administrator); on Core HR > Employee, New Employee form (/employee) open | G22: 1. Observe the Employee Code field on the new form | H22: Logged in as HRMS admin amit (Amit Kumar Shaji, role HRMS / Administrator); on Core HR > Employee, New Employee form (/employee) open → Observe the Employee Code field on the new form | I22: Employee Code is pre-filled/assigned automatically and the input is disabled | J22: UI | K22: Major | L22: High | M22: Automated (Linear Run) | N22: Linear 001 Employee — createRunEmployee | O22: Passed (19 Oct 2026) | R22: /employee | S22: SRS FR-CH-002 says code is overridable; live build disables it — confirm intended behaviour
A23: TC-CHR-022 | B23: Employee | C23: Create employee | D23: Reports To and login fields appear after Role Group + User Level | E23: Logged in as HRMS admin amit (Amit Kumar Shaji, role HRMS / Administrator); on Core HR > Employee, New Employee form (/employee) open | G23: 1. Open the form 2. Observe Reports To / Login Username 3. Choose Role Group Staff and User Level Team Member | H23: Logged in as HRMS admin amit (Amit Kumar Shaji, role HRMS / Administrator); on Core HR > Employee, New Employee form (/employee) open → Open the form → Observe Reports To / Login Username → Choose Role Group Staff and User Level Team Member | I23: Reports To, Login Username, Can Login (ticked by default) and All Branches render only after both are chosen; Reports To options load | J23: UI | K23: Major | L23: High | M23: Automated (Linear Run) | N23: Linear 001 Employee — createRunEmployee | O23: Passed (19 Oct 2026) | R23: /employee
A24: TC-CHR-023 | B24: Employee | C24: Create employee | D24: Same as Phone copies phone to WhatsApp | E24: Logged in as HRMS admin amit (Amit Kumar Shaji, role HRMS / Administrator); on Core HR > Employee, New Employee form (/employee) open | F24: Phone: 9876543210 | G24: 1. Enter Phone 2. Tick Same as Phone | H24: Logged in as HRMS admin amit (Amit Kumar Shaji, role HRMS / Administrator); on Core HR > Employee, New Employee form (/employee) open → Enter Phone → Tick Same as Phone | I24: WhatsApp number equals the phone and is not separately editable while ticked | J24: Positive | K24: Major | L24: Medium | M24: Automated (Linear Run) | N24: Linear 001 Employee — createRunEmployee | O24: Passed (19 Oct 2026) | R24: /employee
A25: TC-CHR-024 | B25: Employee | C25: Create employee | D25: Same as Present copies the address | E25: Logged in as HRMS admin amit (Amit Kumar Shaji, role HRMS / Administrator); on Core HR > Employee, New Employee form (/employee) open | G25: 1. Fill present Country/State/City/Pincode/Address lines 2. Tick Same as Present 3. Save 4. Open the profile Address tab | H25: Logged in as HRMS admin amit (Amit Kumar Shaji, role HRMS / Administrator); on Core HR > Employee, New Employee form (/employee) open → Fill present Country/State/City/Pincode/Address lines → Tick Same as Present → Save → Open the profile Address tab | I25: Permanent address inputs hide; saved permanent address equals present address | J25: Positive | K25: Major | L25: Medium | M25: Automated (Linear Run) | N25: Linear 001 Employee — createRunEmployee | O25: Passed (19 Oct 2026) | R25: /employee | T25: FR-CH-014
A26: TC-CHR-025 | B26: Employee | C26: Create employee | D26: Address Country → State → City cascade | E26: Logged in as HRMS admin amit (Amit Kumar Shaji, role HRMS / Administrator); on Core HR > Employee, New Employee form (/employee) open | G26: 1. Choose Country India 2. Open State 3. Choose Kerala 4. Open City | H26: Logged in as HRMS admin amit (Amit Kumar Shaji, role HRMS / Administrator); on Core HR > Employee, New Employee form (/employee) open → Choose Country India → Open State → Choose Kerala → Open City | I26: State list loads only after country; City list only after state; changing Country clears State and City | J26: Positive | K26: Major | L26: Medium | M26: Not Automated | O26: Not Executed | R26: /employee
A27: TC-CHR-026 | B27: Employee | C27: Create employee | D27: Create with all optional fields filled | E27: Logged in as HRMS admin amit (Amit Kumar Shaji, role HRMS / Administrator); on Core HR > Employee, New Employee form (/employee) open | F27: Honorific Mr; Marital Single; Work Location Office | G27: 1. Fill all mandatory fields 2. Also fill Honorific, Marital Status, Work Location, both addresses, photo 3. Save | H27: Logged in as HRMS admin amit (Amit Kumar Shaji, role HRMS / Administrator); on Core HR > Employee, New Employee form (/employee) open → Fill all mandatory fields → Also fill Honorific, Marital Status, Work Location, both addresses, photo → Save | I27: Employee saved; all optional values visible on the profile view | J27: Positive | K27: Major | L27: Medium | M27: Not Automated | O27: Not Executed | R27: /employee
